<?xml version="1.0" ?>
<!-- =================================================================================== -->
<!-- |    This document was autogenerated by xacro from arm.urdf.xacro                 | -->
<!-- |    EDITING THIS FILE BY HAND IS NOT RECOMMENDED                                 | -->
<!-- =================================================================================== -->
<robot name="arm" xmlns:xacro="http://www.ros.org/wiki/xacro">
  <!-- Joints Control in Gazebo -->
  <gazebo>
    <plugin filename="libgazebo_ros_control.so" name="gazebo_ros_control">
      <robotNamespace>/arm</robotNamespace>
      <robotSimType>gazebo_ros_control/DefaultRobotHWSim</robotSimType>
    </plugin>
  </gazebo>
  <!-- Materials -->
  <material name="orange">
    <color rgba="1.00 0.67 0.02 1.00"/>
  </material>
  <material name="gray">
    <color rgba="0.80 0.80 0.80 1.00"/>
  </material>
  <!-- World frame (for Gazebo) -->
  <link name="world"/>
  <!-- Arm fixed to world frame  -->
  <joint name="world_foot_joint" type="fixed">
    <parent link="world"/>
    <child link="foot"/>
    <origin rpy="0.0 0 0.0" xyz="0.0 0.0 0.0"/>
  </joint>
  <joint name="foot_leg_joint" type="revolute">
    <parent link="foot"/>
    <child link="leg"/>
    <origin rpy="0 0 0" xyz="0 0 0.04"/>
    <axis xyz="1 0 0"/>
    <limit effort="40.0" lower="-3" upper="3" velocity="1.0"/>
  </joint>
  <!-- Required for ROS control -->
  <transmission name="foot_leg_transmission">
    <type>transmission_interface/SimpleTransmission</type>
    <joint name="foot_leg_joint">
      <hardwareInterface>hardware_interface/EffortJointInterface</hardwareInterface>
    </joint>
    <actuator name="foot_leg_actuator">
      <hardwareInterface>EffortJointInterface</hardwareInterface>
      <mechanicalReduction>1</mechanicalReduction>
    </actuator>
  </transmission>
  <link name="foot">
    <visual>
      <origin rpy="0 0 0" xyz="0 0 0.02"/>
      <geometry>
        <box size="0.02 0.02 0.04"/>
      </geometry>
      <material name="orange"/>
    </visual>
    <collision>
      <origin rpy="0 0 0" xyz="0 0 0.02"/>
      <geometry>
        <box size="0.02 0.02 0.04"/>
      </geometry>
    </collision>
    <inertial>
      <origin rpy="0 0 0" xyz="0 0 0.02"/>
      <mass value="1"/>
      <inertia ixx="0.000166666666667" ixy="0" ixz="0" iyy="0.000166666666667" iyz="0" izz="6.66666666667e-05"/>
    </inertial>
    <visual>
      <origin rpy="0 1.5 0" xyz="0 0 0.04"/>
      <geometry>
        <cylinder length="0.025" radius="0.018"/>
      </geometry>
      <material name="gray"/>
    </visual>
    <collision>
      <origin rpy="0 1.5 0" xyz="0 0 0.04"/>
      <geometry>
        <cylinder length="0.025" radius="0.018"/>
      </geometry>
    </collision>
  </link>
  <gazebo reference="foot">
    <material>Gazebo/Orange</material>
  </gazebo>
  <joint name="leg_arm_joint" type="revolute">
    <parent link="leg"/>
    <child link="arm"/>
    <origin rpy="0 0 0" xyz="0 0 0.4"/>
    <axis xyz="1 0 0"/>
    <limit effort="40.0" lower="-3" upper="3" velocity="1.0"/>
  </joint>
  <!-- Required for ROS control -->
  <transmission name="leg_arm_transmission">
    <type>transmission_interface/SimpleTransmission</type>
    <joint name="leg_arm_joint">
      <hardwareInterface>hardware_interface/EffortJointInterface</hardwareInterface>
    </joint>
    <actuator name="leg_arm_actuator">
      <hardwareInterface>EffortJointInterface</hardwareInterface>
      <mechanicalReduction>1</mechanicalReduction>
    </actuator>
  </transmission>
  <link name="leg">
    <visual>
      <origin rpy="0 0 0" xyz="0 0 0.2"/>
      <geometry>
        <box size="0.02 0.02 0.4"/>
      </geometry>
      <material name="orange"/>
    </visual>
    <collision>
      <origin rpy="0 0 0" xyz="0 0 0.2"/>
      <geometry>
        <box size="0.02 0.02 0.4"/>
      </geometry>
    </collision>
    <inertial>
      <origin rpy="0 0 0" xyz="0 0 0.2"/>
      <mass value="1"/>
      <inertia ixx="0.0133666666667" ixy="0" ixz="0" iyy="0.0133666666667" iyz="0" izz="6.66666666667e-05"/>
    </inertial>
    <visual>
      <origin rpy="0 1.5 0" xyz="0 0 0.4"/>
      <geometry>
        <cylinder length="0.025" radius="0.018"/>
      </geometry>
      <material name="gray"/>
    </visual>
    <collision>
      <origin rpy="0 1.5 0" xyz="0 0 0.4"/>
      <geometry>
        <cylinder length="0.025" radius="0.018"/>
      </geometry>
    </collision>
  </link>
  <gazebo reference="leg">
    <material>Gazebo/Orange</material>
  </gazebo>
  <!-- End effector -->
  <link name="arm">
    <visual>
      <origin rpy="0 0 0" xyz="0 0 0.15"/>
      <geometry>
        <box size="0.02 0.02 0.3"/>
      </geometry>
      <material name="orange"/>
    </visual>
    <collision>
      <origin rpy="0 0 0" xyz="0 0 0.15"/>
      <geometry>
        <box size="0.02 0.02 0.3"/>
      </geometry>
    </collision>
    <inertial>
      <origin rpy="0 0 0" xyz="0 0 0.15"/>
      <mass value="1"/>
      <inertia ixx="0.00753333333333" ixy="0" ixz="0" iyy="0.00753333333333" iyz="0" izz="6.66666666667e-05"/>
    </inertial>
    <visual>
      <origin rpy="0 1.5 0" xyz="0 0 0.3"/>
      <geometry>
        <cylinder length="0.025" radius="0.018"/>
      </geometry>
      <material name="gray"/>
    </visual>
    <collision>
      <origin rpy="0 1.5 0" xyz="0 0 0.3"/>
      <geometry>
        <cylinder length="0.025" radius="0.018"/>
      </geometry>
    </collision>
  </link>
  <gazebo reference="arm">
    <material>Gazebo/Orange</material>
  </gazebo>
</robot>
